Workbook
Name Slicer_Denial_or_Exception: #N/A
Name Slicer_Payment_Status: #N/A
Name Slicer_Region: #N/A
Name Slicer_Service_Category: #N/A

Sheet revenue_billing_raw_data_sample
A1: Invoice_ID | B1: Customer_Name | C1: Invoice_Date | D1: Due_Date | E1: Payment_Date | F1: Region | G1: Service_Category | H1: Billed_Amount | I1: Paid_Amount | J1: Payment_Status | K1: Denial_or_Exception | L1: Exception_Reason | M1: Account_Manager
A2: INV-1017 | B2: Hillcrest Diagnostics | C2: 45717 | D2: 45747 | F2: Central | G2: Billing Support | H2: 342.85 | I2: 0 | J2: Unpaid | K2: No | L2: None | M2: K. Brown
A3: INV-1022 | B3: Summit Health | C3: 45720 | D3: 45750 | E3: 45732 | F3: North | G3: Revenue Audit | H3: 1012.03 | I3: 1012.03 | J3: Paid | K3: Yes | L3: Eligibility issue | M3: R. Nguyen
A4: INV-1238 | B4: Summit Health | C4: 45720 | D4: 45750 | E4: 45765 | F4: East | G4: Claims Review | H4: 2286.94 | I4: 2286.94 | J4: Paid | K4: No | L4: None | M4: A. Lopez
A5: INV-1037 | B5: Hillcrest Diagnostics | C5: 45721 | D5: 45751 | F5: Central | G5: Billing Support | H5: 527.89 | I5: 0 | J5: Unpaid | K5: Yes | L5: Denied claim | M5: R. Nguyen
A6: INV-1234 | B6: Blue Ridge Medical | C6: 45721 | D6: 45751 | F6: East | G6: RCM Consulting | H6: 2036.95 | I6: 0 | J6: Unpaid | K6: Yes | L6: Coding issue | M6: S. Patel
A7: INV-1239 | B7: Red Oak Wellness | C7: 45722 | D7: 45752 | E7: 45749 | F7: East | G7: Revenue Audit | H7: 4371.67 | I7: 4371.67 | J7: Paid | K7: No | L7: None | M7: M. Diaz
A8: INV-1179 | B8: Westgate Family Health | C8: 45727 | D8: 45757 | F8: West | G8: Claims Review | H8: 3042.68 | I8: 0 | J8: Unpaid | K8: Yes | L8: Denied claim | M8: J. Smith
A9: INV-1210 | B9: Parkview Internal Medicine | C9: 45728 | D9: 45758 | E9: 45739 | F9: North | G9: Claims Review | H9: 2328.92 | I9: 2328.92 | J9: Paid | K9: No | L9: None | M9: S. Patel
A10: INV-1246 | B10: Valley Care Center | C10: 45728 | D10: 45758 | E10: 45780 | F10: West | G10: Billing Support | H10: 1940.77 | I10: 1940.77 | J10: Paid | K10: Yes | L10: Eligibility issue | M10: J. Smith
A11: INV-1001 | B11: Oak Health Group | C11: 45729 | D11: 45759 | E11: 45771 | F11: East | G11: Imaging | H11: 1804.67 | I11: 1804.67 | J11: Paid | K11: No | L11: None | M11: A. Lopez
A12: INV-1123 | B12: Parkview Internal Medicine | C12: 45729 | D12: 45759 | E12: 45781 | F12: Central | G12: RCM Consulting | H12: 8339 | I12: 8339 | J12: Paid | K12: Yes | L12: Missing info | M12: M. Diaz
A13: INV-1065 | B13: Westgate Family Health | C13: 45730 | D13: 45760 | E13: 45767 | F13: West | G13: RCM Consulting | H13: 6371.4 | I13: 6371.4 | J13: Paid | K13: No | L13: None | M13: S. Patel
A14: INV-1190 | B14: Pioneer Care | C14: 45732 | D14: 45762 | E14: 45763 | F14: South | G14: RCM Consulting | H14: 7294.23 | I14: 7294.23 | J14: Paid | K14: Yes | L14: Eligibility issue | M14: R. Nguyen
A15: INV-1010 | B15: Summit Health | C15: 45733 | D15: 45763 | F15: East | G15: Claims Review | H15: 764.75 | I15: 0 | J15: Unpaid | K15: Yes | L15: Eligibility issue | M15: M. Diaz
A16: INV-1233 | B16: Pioneer Care | C16: 45735 | D16: 45765 | F16: West | G16: Claims Review | H16: 4246.43 | I16: 0 | J16: Unpaid | K16: No | L16: None | M16: A. Lopez
A17: INV-1094 | B17: Red Oak Wellness | C17: 45737 | D17: 45767 | F17: South | G17: Claims Review | H17: 3106.04 | I17: 0 | J17: Unpaid | K17: Yes | L17: Coding issue | M17: S. Patel
A18: INV-1181 | B18: Trinity Wellness | C18: 45739 | D18: 45769 | E18: 45776 | F18: East | G18: RCM Consulting | H18: 7545.37 | I18: 7545.37 | J18: Paid | K18: No | L18: None | M18: M. Diaz
A19: INV-1253 | B19: Summit Health | C19: 45739 | D19: 45769 | F19: West | G19: Claims Review | H19: 2659.04 | I19: 888.34 | J19: Partial | K19: No | L19: None | M19: A. Lopez
A20: INV-1110 | B20: NorthStar Clinic | C20: 45740 | D20: 45770 | E20: 45774 | F20: East | G20: Lab Services | H20: 1511.24 | I20: 1511.24 | J20: Paid | K20: No | L20: None | M20: M. Diaz
A21: INV-1203 | B21: Metro Family Care | C21: 45740 | D21: 45770 | E21: 45749 | F21: Central | G21: Billing Support | H21: 763.78 | I21: 763.78 | J21: Paid | K21: No | L21: None | M21: R. Nguyen
A22: INV-1066 | B22: Pioneer Care | C22: 45742 | D22: 45772 | E22: 45774 | F22: East | G22: Claims Review | H22: 1346.64 | I22: 1346.64 | J22: Paid | K22: No | L22: None | M22: M. Diaz
A23: INV-1083 | B23: Blue Ridge Medical | C23: 45744 | D23: 45774 | E23: 45758 | F23: Central | G23: Billing Support | H23: 2377 | I23: 2377 | J23: Paid | K23: No | L23: None | M23: R. Nguyen
A24: INV-1156 | B24: Red Oak Wellness | C24: 45745 | D24: 45775 | E24: 45757 | F24: East | G24: RCM Consulting | H24: 3621.18 | I24: 3621.18 | J24: Paid | K24: Yes | L24: Eligibility issue | M24: J. Smith
A25: INV-1245 | B25: Riverside Health | C25: 45745 | D25: 45775 | E25: 45796 | F25: West | G25: Imaging | H25: 3791.06 | I25: 3791.06 | J25: Paid | K25: No | L25: None | M25: S. Patel
A26: INV-1161 | B26: Cedar Grove Health | C26: 45750 | D26: 45780 | E26: 45800 | F26: East | G26: Lab Services | H26: 2502.98 | I26: 2502.98 | J26: Paid | K26: No | L26: None | M26: S. Patel
A27: INV-1138 | B27: Parkview Internal Medicine | C27: 45751 | D27: 45781 | E27: 45805 | F27: North | G27: Lab Services | H27: 1738.82 | I27: 1015.16 | J27: Partial | K27: Yes | L27: Denied claim | M27: J. Smith
A28: INV-1180 | B28: Lakeside Imaging | C28: 45751 | D28: 45781 | E28: 45780 | F28: East | G28: Imaging | H28: 5531.15 | I28: 5531.15 | J28: Paid | K28: No | L28: None | M28: R. Nguyen
A29: INV-1091 | B29: Trinity Wellness | C29: 45753 | D29: 45783 | E29: 45803 | F29: North | G29: Imaging | H29: 5084.32 | I29: 2610.76 | J29: Partial | K29: No | L29: None | M29: M. Diaz
A30: INV-1086 | B30: Valley Care Center | C30: 45760 | D30: 45790 | E30: 45782 | F30: South | G30: Lab Services | H30: 2769.77 | I30: 2769.77 | J30: Paid | K30: No | L30: None | M30: S. Patel
A31: INV-1013 | B31: Parkview Internal Medicine | C31: 45763 | D31: 45793 | E31: 45834 | F31: North | G31: Lab Services | H31: 2345.08 | I31: 1127.66 | J31: Partial | K31: Yes | L31: Underpayment | M31: A. Lopez
... A39: INV-1100 | B39: Riverside Health | C39: 45777 | D39: 45807 | E39: 45807 | F39: South | G39: Claims Review | H39: 1667.45 | I39: 1397.57 | J39: Partial | K39: Yes | L39: Coding issue | M39: R. Nguyen
A40: INV-1214 | B40: Canyon Creek Medical | C40: 45777 | D40: 45807 | F40: South | G40: Lab Services | H40: 1556.91 | I40: 0 | J40: Unpaid | K40: Yes | L40: Eligibility issue | M40: K. Brown
A41: INV-1099 | B41: Parkview Internal Medicine | C41: 45779 | D41: 45809 | E41: 45805 | F41: North | G41: Revenue Audit | H41: 4936.36 | I41: 2869.76 | J41: Partial | K41: Yes | L41: Underpayment | M41: S. Patel
A42: INV-1194 | B42: Horizon Medical | C42: 45779 | D42: 45809 | F42: South | G42: Lab Services | H42: 935.23 | I42: 688.62 | J42: Partial | K42: No | L42: None | M42: K. Brown
A43: INV-1171 | B43: Hillcrest Diagnostics | C43: 45780 | D43: 45810 | F43: East | G43: Lab Services | H43: 1245.65 | I43: 0 | J43: Unpaid | K43: Yes | L43: Missing info | M43: A. Lopez
A44: INV-1019 | B44: Westgate Family Health | C44: 45781 | D44: 45811 | E44: 45827 | F44: South | G44: Revenue Audit | H44: 5718.3 | I44: 5718.3 | J44: Paid | K44: No | L44: None | M44: K. Brown
A45: INV-1148 | B45: Pioneer Care | C45: 45783 | D45: 45813 | E45: 45813 | F45: West | G45: RCM Consulting | H45: 2994.86 | I45: 2994.86 | J45: Paid | K45: No | L45: None | M45: R. Nguyen
A46: INV-1131 | B46: NorthStar Clinic | C46: 45784 | D46: 45814 | E46: 45800 | F46: North | G46: Billing Support | H46: 1595.48 | I46: 1595.48 | J46: Paid | K46: No | L46: None | M46: A. Lopez
A47: INV-1170 | B47: Canyon Creek Medical | C47: 45787 | D47: 45817 | E47: 45840 | F47: East | G47: Lab Services | H47: 1889.83 | I47: 1889.83 | J47: Paid | K47: No | L47: None | M47: R. Nguyen
...

Sheet Cleaned_Data
A1: Invoice_ID | B1: Customer_Name | C1: Invoice_Date | D1: Due_Date | E1: Payment_Date | F1: Region | G1: Service_Category | H1: Billed_Amount | I1: Paid_Amount | J1: Payment_Status | K1: Denial_or_Exception | L1: Exception_Reason | M1: Account_Manager | N1: Outstanding_Balance | O1: Days_to_Pay | P1: Days_Past_Due | Q1: Aging_Bucket | R1: Month | S1: Year_Month
A2: INV-1017 | B2: Hillcrest Diagnostics | C2: 45717 | D2: 45747 | F2: Central | G2: Billing Support | H2: 342.85 | I2: 0 | J2: Unpaid | K2: No | L2: None | M2: K. Brown | N2: =H2-I2 -> 342.85 | O2: =IF(E2="","",E2-C2) | P2: =IF(N2<=0,0,TODAY()-D2) -> 350 | Q2: =IF(N2<=0,"Paid",IF(P2<=0,"Current",IF(P2<=30,"1-30",IF(P2<=60,"31-60",IF(P2<=90,"61-90","90+"))))) -> 90+ | R2: =TEXT(C2,"mmm") -> Mar | S2: =TEXT(C2,"yyyy-mm") -> 2025-03
A3: INV-1022 | B3: Summit Health | C3: 45720 | D3: 45750 | E3: 45732 | F3: North | G3: Revenue Audit | H3: 1012.03 | I3: 1012.03 | J3: Paid | K3: Yes | L3: Eligibility issue | M3: R. Nguyen | N3: =H3-I3 -> 0 | O3: =IF(E3="","",E3-C3) -> 12 | P3: =IF(N3<=0,0,TODAY()-D3) -> 0 | Q3: =IF(N3<=0,"Paid",IF(P3<=0,"Current",IF(P3<=30,"1-30",IF(P3<=60,"31-60",IF(P3<=90,"61-90","90+"))))) -> Paid | R3: =TEXT(C3,"mmm") -> Mar | S3: =TEXT(C3,"yyyy-mm") -> 2025-03
A4: INV-1238 | B4: Summit Health | C4: 45720 | D4: 45750 | E4: 45765 | F4: East | G4: Claims Review | H4: 2286.94 | I4: 2286.94 | J4: Paid | K4: No | L4: None | M4: A. Lopez | N4: =H4-I4 -> 0 | O4: =IF(E4="","",E4-C4) -> 45 | P4: =IF(N4<=0,0,TODAY()-D4) -> 0 | Q4: =IF(N4<=0,"Paid",IF(P4<=0,"Current",IF(P4<=30,"1-30",IF(P4<=60,"31-60",IF(P4<=90,"61-90","90+"))))) -> Paid | R4: =TEXT(C4,"mmm") -> Mar | S4: =TEXT(C4,"yyyy-mm") -> 2025-03
A5: INV-1037 | B5: Hillcrest Diagnostics | C5: 45721 | D5: 45751 | F5: Central | G5: Billing Support | H5: 527.89 | I5: 0 | J5: Unpaid | K5: Yes | L5: Denied claim | M5: R. Nguyen | N5: =H5-I5 -> 527.89 | O5: =IF(E5="","",E5-C5) | P5: =IF(N5<=0,0,TODAY()-D5) -> 346 | Q5: =IF(N5<=0,"Paid",IF(P5<=0,"Current",IF(P5<=30,"1-30",IF(P5<=60,"31-60",IF(P5<=90,"61-90","90+"))))) -> 90+ | R5: =TEXT(C5,"mmm") -> Mar | S5: =TEXT(C5,"yyyy-mm") -> 2025-03
A6: INV-1234 | B6: Blue Ridge Medical | C6: 45721 | D6: 45751 | F6: East | G6: RCM Consulting | H6: 2036.95 | I6: 0 | J6: Unpaid | K6: Yes | L6: Coding issue | M6: S. Patel | N6: =H6-I6 -> 2036.95 | O6: =IF(E6="","",E6-C6) | P6: =IF(N6<=0,0,TODAY()-D6) -> 346 | Q6: =IF(N6<=0,"Paid",IF(P6<=0,"Current",IF(P6<=30,"1-30",IF(P6<=60,"31-60",IF(P6<=90,"61-90","90+"))))) -> 90+ | R6: =TEXT(C6,"mmm") -> Mar | S6: =TEXT(C6,"yyyy-mm") -> 2025-03
A7: INV-1239 | B7: Red Oak Wellness | C7: 45722 | D7: 45752 | E7: 45749 | F7: East | G7: Revenue Audit | H7: 4371.67 | I7: 4371.67 | J7: Paid | K7: No | L7: None | M7: M. Diaz | N7: =H7-I7 -> 0 | O7: =IF(E7="","",E7-C7) -> 27 | P7: =IF(N7<=0,0,TODAY()-D7) -> 0 | Q7: =IF(N7<=0,"Paid",IF(P7<=0,"Current",IF(P7<=30,"1-30",IF(P7<=60,"31-60",IF(P7<=90,"61-90","90+"))))) -> Paid | R7: =TEXT(C7,"mmm") -> Mar | S7: =TEXT(C7,"yyyy-mm") -> 2025-03
A8: INV-1179 | B8: Westgate Family Health | C8: 45727 | D8: 45757 | F8: West | G8: Claims Review | H8: 3042.68 | I8: 0 | J8: Unpaid | K8: Yes | L8: Denied claim | M8: J. Smith | N8: =H8-I8 -> 3042.68 | O8: =IF(E8="","",E8-C8) | P8: =IF(N8<=0,0,TODAY()-D8) -> 340 | Q8: =IF(N8<=0,"Paid",IF(P8<=0,"Current",IF(P8<=30,"1-30",IF(P8<=60,"31-60",IF(P8<=90,"61-90","90+"))))) -> 90+ | R8: =TEXT(C8,"mmm") -> Mar | S8: =TEXT(C8,"yyyy-mm") -> 2025-03
A9: INV-1210 | B9: Parkview Internal Medicine | C9: 45728 | D9: 45758 | E9: 45739 | F9: North | G9: Claims Review | H9: 2328.92 | I9: 2328.92 | J9: Paid | K9: No | L9: None | M9: S. Patel | N9: =H9-I9 -> 0 | O9: =IF(E9="","",E9-C9) -> 11 | P9: =IF(N9<=0,0,TODAY()-D9) -> 0 | Q9: =IF(N9<=0,"Paid",IF(P9<=0,"Current",IF(P9<=30,"1-30",IF(P9<=60,"31-60",IF(P9<=90,"61-90","90+"))))) -> Paid | R9: =TEXT(C9,"mmm") -> Mar | S9: =TEXT(C9,"yyyy-mm") -> 2025-03
A10: INV-1246 | B10: Valley Care Center | C10: 45728 | D10: 45758 | E10: 45780 | F10: West | G10: Billing Support | H10: 1940.77 | I10: 1940.77 | J10: Paid | K10: Yes | L10: Eligibility issue | M10: J. Smith | N10: =H10-I10 -> 0 | O10: =IF(E10="","",E10-C10) -> 52 | P10: =IF(N10<=0,0,TODAY()-D10) -> 0 | Q10: =IF(N10<=0,"Paid",IF(P10<=0,"Current",IF(P10<=30,"1-30",IF(P10<=60,"31-60",IF(P10<=90,"61-90","90+"))))) -> Paid | R10: =TEXT(C10,"mmm") -> Mar | S10: =TEXT(C10,"yyyy-mm") -> 2025-03
A11: INV-1001 | B11: Oak Health Group | C11: 45729 | D11: 45759 | E11: 45771 | F11: East | G11: Imaging | H11: 1804.67 | I11: 1804.67 | J11: Paid | K11: No | L11: None | M11: A. Lopez | N11: =H11-I11 -> 0 | O11: =IF(E11="","",E11-C11) -> 42 | P11: =IF(N11<=0,0,TODAY()-D11) -> 0 | Q11: =IF(N11<=0,"Paid",IF(P11<=0,"Current",IF(P11<=30,"1-30",IF(P11<=60,"31-60",IF(P11<=90,"61-90","90+"))))) -> Paid | R11: =TEXT(C11,"mmm") -> Mar | S11: =TEXT(C11,"yyyy-mm") -> 2025-03
A12: INV-1123 | B12: Parkview Internal Medicine | C12: 45729 | D12: 45759 | E12: 45781 | F12: Central | G12: RCM Consulting | H12: 8339 | I12: 8339 | J12: Paid | K12: Yes | L12: Missing info | M12: M. Diaz | N12: =H12-I12 -> 0 | O12: =IF(E12="","",E12-C12) -> 52 | P12: =IF(N12<=0,0,TODAY()-D12) -> 0 | Q12: =IF(N12<=0,"Paid",IF(P12<=0,"Current",IF(P12<=30,"1-30",IF(P12<=60,"31-60",IF(P12<=90,"61-90","90+"))))) -> Paid | R12: =TEXT(C12,"mmm") -> Mar | S12: =TEXT(C12,"yyyy-mm") -> 2025-03
A13: INV-1065 | B13: Westgate Family Health | C13: 45730 | D13: 45760 | E13: 45767 | F13: West | G13: RCM Consulting | H13: 6371.4 | I13: 6371.4 | J13: Paid | K13: No | L13: None | M13: S. Patel | N13: =H13-I13 -> 0 | O13: =IF(E13="","",E13-C13) -> 37 | P13: =IF(N13<=0,0,TODAY()-D13) -> 0 | Q13: =IF(N13<=0,"Paid",IF(P13<=0,"Current",IF(P13<=30,"1-30",IF(P13<=60,"31-60",IF(P13<=90,"61-90","90+"))))) -> Paid | R13: =TEXT(C13,"mmm") -> Mar | S13: =TEXT(C13,"yyyy-mm") -> 2025-03
A14: INV-1190 | B14: Pioneer Care | C14: 45732 | D14: 45762 | E14: 45763 | F14: South | G14: RCM Consulting | H14: 7294.23 | I14: 7294.23 | J14: Paid | K14: Yes | L14: Eligibility issue | M14: R. Nguyen | N14: =H14-I14 -> 0 | O14: =IF(E14="","",E14-C14) -> 31 | P14: =IF(N14<=0,0,TODAY()-D14) -> 0 | Q14: =IF(N14<=0,"Paid",IF(P14<=0,"Current",IF(P14<=30,"1-30",IF(P14<=60,"31-60",IF(P14<=90,"61-90","90+"))))) -> Paid | R14: =TEXT(C14,"mmm") -> Mar | S14: =TEXT(C14,"yyyy-mm") -> 2025-03
A15: INV-1010 | B15: Summit Health | C15: 45733 | D15: 45763 | F15: East | G15: Claims Review | H15: 764.75 | I15: 0 | J15: Unpaid | K15: Yes | L15: Eligibility issue | M15: M. Diaz | N15: =H15-I15 -> 764.75 | O15: =IF(E15="","",E15-C15) | P15: =IF(N15<=0,0,TODAY()-D15) -> 334 | Q15: =IF(N15<=0,"Paid",IF(P15<=0,"Current",IF(P15<=30,"1-30",IF(P15<=60,"31-60",IF(P15<=90,"61-90","90+"))))) -> 90+ | R15: =TEXT(C15,"mmm") -> Mar | S15: =TEXT(C15,"yyyy-mm") -> 2025-03
A16: INV-1233 | B16: Pioneer Care | C16: 45735 | D16: 45765 | F16: West | G16: Claims Review | H16: 4246.43 | I16: 0 | J16: Unpaid | K16: No | L16: None | M16: A. Lopez | N16: =H16-I16 -> 4246.43 | O16: =IF(E16="","",E16-C16) | P16: =IF(N16<=0,0,TODAY()-D16) -> 332 | Q16: =IF(N16<=0,"Paid",IF(P16<=0,"Current",IF(P16<=30,"1-30",IF(P16<=60,"31-60",IF(P16<=90,"61-90","90+"))))) -> 90+ | R16: =TEXT(C16,"mmm") -> Mar | S16: =TEXT(C16,"yyyy-mm") -> 2025-03
A17: INV-1094 | B17: Red Oak Wellness | C17: 45737 | D17: 45767 | F17: South | G17: Claims Review | H17: 3106.04 | I17: 0 | J17: Unpaid | K17: Yes | L17: Coding issue | M17: S. Patel | N17: =H17-I17 -> 3106.04 | O17: =IF(E17="","",E17-C17) | P17: =IF(N17<=0,0,TODAY()-D17) -> 330 | Q17: =IF(N17<=0,"Paid",IF(P17<=0,"Current",IF(P17<=30,"1-30",IF(P17<=60,"31-60",IF(P17<=90,"61-90","90+"))))) -> 90+ | R17: =TEXT(C17,"mmm") -> Mar | S17: =TEXT(C17,"yyyy-mm") -> 2025-03
A18: INV-1181 | B18: Trinity Wellness | C18: 45739 | D18: 45769 | E18: 45776 | F18: East | G18: RCM Consulting | H18: 7545.37 | I18: 7545.37 | J18: Paid | K18: No | L18: None | M18: M. Diaz | N18: =H18-I18 -> 0 | O18: =IF(E18="","",E18-C18) -> 37 | P18: =IF(N18<=0,0,TODAY()-D18) -> 0 | Q18: =IF(N18<=0,"Paid",IF(P18<=0,"Current",IF(P18<=30,"1-30",IF(P18<=60,"31-60",IF(P18<=90,"61-90","90+"))))) -> Paid | R18: =TEXT(C18,"mmm") -> Mar | S18: =TEXT(C18,"yyyy-mm") -> 2025-03
A19: INV-1253 | B19: Summit Health | C19: 45739 | D19: 45769 | F19: West | G19: Claims Review | H19: 2659.04 | I19: 888.34 | J19: Partial | K19: No | L19: None | M19: A. Lopez | N19: =H19-I19 -> 1770.7 | O19: =IF(E19="","",E19-C19) | P19: =IF(N19<=0,0,TODAY()-D19) -> 328 | Q19: =IF(N19<=0,"Paid",IF(P19<=0,"Current",IF(P19<=30,"1-30",IF(P19<=60,"31-60",IF(P19<=90,"61-90","90+"))))) -> 90+ | R19: =TEXT(C19,"mmm") -> Mar | S19: =TEXT(C19,"yyyy-mm") -> 2025-03
A20: INV-1110 | B20: NorthStar Clinic | C20: 45740 | D20: 45770 | E20: 45774 | F20: East | G20: Lab Services | H20: 1511.24 | I20: 1511.24 | J20: Paid | K20: No | L20: None | M20: M. Diaz | N20: =H20-I20 -> 0 | O20: =IF(E20="","",E20-C20) -> 34 | P20: =IF(N20<=0,0,TODAY()-D20) -> 0 | Q20: =IF(N20<=0,"Paid",IF(P20<=0,"Current",IF(P20<=30,"1-30",IF(P20<=60,"31-60",IF(P20<=90,"61-90","90+"))))) -> Paid | R20: =TEXT(C20,"mmm") -> Mar | S20: =TEXT(C20,"yyyy-mm") -> 2025-03
A21: INV-1203 | B21: Metro Family Care | C21: 45740 | D21: 45770 | E21: 45749 | F21: Central | G21: Billing Support | H21: 763.78 | I21: 763.78 | J21: Paid | K21: No | L21: None | M21: R. Nguyen | N21: =H21-I21 -> 0 | O21: =IF(E21="","",E21-C21) -> 9 | P21: =IF(N21<=0,0,TODAY()-D21) -> 0 | Q21: =IF(N21<=0,"Paid",IF(P21<=0,"Current",IF(P21<=30,"1-30",IF(P21<=60,"31-60",IF(P21<=90,"61-90","90+"))))) -> Paid | R21: =TEXT(C21,"mmm") -> Mar | S21: =TEXT(C21,"yyyy-mm") -> 2025-03
A22: INV-1066 | B22: Pioneer Care | C22: 45742 | D22: 45772 | E22: 45774 | F22: East | G22: Claims Review | H22: 1346.64 | I22: 1346.64 | J22: Paid | K22: No | L22: None | M22: M. Diaz | N22: =H22-I22 -> 0 | O22: =IF(E22="","",E22-C22) -> 32 | P22: =IF(N22<=0,0,TODAY()-D22) -> 0 | Q22: =IF(N22<=0,"Paid",IF(P22<=0,"Current",IF(P22<=30,"1-30",IF(P22<=60,"31-60",IF(P22<=90,"61-90","90+"))))) -> Paid | R22: =TEXT(C22,"mmm") -> Mar | S22: =TEXT(C22,"yyyy-mm") -> 2025-03
A23: INV-1083 | B23: Blue Ridge Medical | C23: 45744 | D23: 45774 | E23: 45758 | F23: Central | G23: Billing Support | H23: 2377 | I23: 2377 | J23: Paid | K23: No | L23: None | M23: R. Nguyen | N23: =H23-I23 -> 0 | O23: =IF(E23="","",E23-C23) -> 14 | P23: =IF(N23<=0,0,TODAY()-D23) -> 0 | Q23: =IF(N23<=0,"Paid",IF(P23<=0,"Current",IF(P23<=30,"1-30",IF(P23<=60,"31-60",IF(P23<=90,"61-90","90+"))))) -> Paid | R23: =TEXT(C23,"mmm") -> Mar | S23: =TEXT(C23,"yyyy-mm") -> 2025-03
A24: INV-1156 | B24: Red Oak Wellness | C24: 45745 | D24: 45775 | E24: 45757 | F24: East | G24: RCM Consulting | H24: 3621.18 | I24: 3621.18 | J24: Paid | K24: Yes | L24: Eligibility issue | M24: J. Smith | N24: =H24-I24 -> 0 | O24: =IF(E24="","",E24-C24) -> 12 | P24: =IF(N24<=0,0,TODAY()-D24) -> 0 | Q24: =IF(N24<=0,"Paid",IF(P24<=0,"Current",IF(P24<=30,"1-30",IF(P24<=60,"31-60",IF(P24<=90,"61-90","90+"))))) -> Paid | R24: =TEXT(C24,"mmm") -> Mar | S24: =TEXT(C24,"yyyy-mm") -> 2025-03
A25: INV-1245 | B25: Riverside Health | C25: 45745 | D25: 45775 | E25: 45796 | F25: West | G25: Imaging | H25: 3791.06 | I25: 3791.06 | J25: Paid | K25: No | L25: None | M25: S. Patel | N25: =H25-I25 -> 0 | O25: =IF(E25="","",E25-C25) -> 51 | P25: =IF(N25<=0,0,TODAY()-D25) -> 0 | Q25: =IF(N25<=0,"Paid",IF(P25<=0,"Current",IF(P25<=30,"1-30",IF(P25<=60,"31-60",IF(P25<=90,"61-90","90+"))))) -> Paid | R25: =TEXT(C25,"mmm") -> Mar | S25: =TEXT(C25,"yyyy-mm") -> 2025-03
A26: INV-1161 | B26: Cedar Grove Health | C26: 45750 | D26: 45780 | E26: 45800 | F26: East | G26: Lab Services | H26: 2502.98 | I26: 2502.98 | J26: Paid | K26: No | L26: None | M26: S. Patel | N26: =H26-I26 -> 0 | O26: =IF(E26="","",E26-C26) -> 50 | P26: =IF(N26<=0,0,TODAY()-D26) -> 0 | Q26: =IF(N26<=0,"Paid",IF(P26<=0,"Current",IF(P26<=30,"1-30",IF(P26<=60,"31-60",IF(P26<=90,"61-90","90+"))))) -> Paid | R26: =TEXT(C26,"mmm") -> Apr | S26: =TEXT(C26,"yyyy-mm") -> 2025-04
A27: INV-1138 | B27: Parkview Internal Medicine | C27: 45751 | D27: 45781 | E27: 45805 | F27: North | G27: Lab Services | H27: 1738.82 | I27: 1015.16 | J27: Partial | K27: Yes | L27: Denied claim | M27: J. Smith | N27: =H27-I27 -> 723.66 | O27: =IF(E27="","",E27-C27) -> 54 | P27: =IF(N27<=0,0,TODAY()-D27) -> 316 | Q27: =IF(N27<=0,"Paid",IF(P27<=0,"Current",IF(P27<=30,"1-30",IF(P27<=60,"31-60",IF(P27<=90,"61-90","90+"))))) -> 90+ | R27: =TEXT(C27,"mmm") -> Apr | S27: =TEXT(C27,"yyyy-mm") -> 2025-04
A28: INV-1180 | B28: Lakeside Imaging | C28: 45751 | D28: 45781 | E28: 45780 | F28: East | G28: Imaging | H28: 5531.15 | I28: 5531.15 | J28: Paid | K28: No | L28: None | M28: R. Nguyen | N28: =H28-I28 -> 0 | O28: =IF(E28="","",E28-C28) -> 29 | P28: =IF(N28<=0,0,TODAY()-D28) -> 0 | Q28: =IF(N28<=0,"Paid",IF(P28<=0,"Current",IF(P28<=30,"1-30",IF(P28<=60,"31-60",IF(P28<=90,"61-90","90+"))))) -> Paid | R28: =TEXT(C28,"mmm") -> Apr | S28: =TEXT(C28,"yyyy-mm") -> 2025-04
A29: INV-1091 | B29: Trinity Wellness | C29: 45753 | D29: 45783 | E29: 45803 | F29: North | G29: Imaging | H29: 5084.32 | I29: 2610.76 | J29: Partial | K29: No | L29: None | M29: M. Diaz | N29: =H29-I29 -> 2473.56 | O29: =IF(E29="","",E29-C29) -> 50 | P29: =IF(N29<=0,0,TODAY()-D29) -> 314 | Q29: =IF(N29<=0,"Paid",IF(P29<=0,"Current",IF(P29<=30,"1-30",IF(P29<=60,"31-60",IF(P29<=90,"61-90","90+"))))) -> 90+ | R29: =TEXT(C29,"mmm") -> Apr | S29: =TEXT(C29,"yyyy-mm") -> 2025-04
A30: INV-1086 | B30: Valley Care Center | C30: 45760 | D30: 45790 | E30: 45782 | F30: South | G30: Lab Services | H30: 2769.77 | I30: 2769.77 | J30: Paid | K30: No | L30: None | M30: S. Patel | N30: =H30-I30 -> 0 | O30: =IF(E30="","",E30-C30) -> 22 | P30: =IF(N30<=0,0,TODAY()-D30) -> 0 | Q30: =IF(N30<=0,"Paid",IF(P30<=0,"Current",IF(P30<=30,"1-30",IF(P30<=60,"31-60",IF(P30<=90,"61-90","90+"))))) -> Paid | R30: =TEXT(C30,"mmm") -> Apr | S30: =TEXT(C30,"yyyy-mm") -> 2025-04
A31: INV-1013 | B31: Parkview Internal Medicine | C31: 45763 | D31: 45793 | E31: 45834 | F31: North | G31: Lab Services | H31: 2345.08 | I31: 1127.66 | J31: Partial | K31: Yes | L31: Underpayment | M31: A. Lopez | N31: =H31-I31 -> 1217.42 | O31: =IF(E31="","",E31-C31) -> 71 | P31: =IF(N31<=0,0,TODAY()-D31) -> 304 | Q31: =IF(N31<=0,"Paid",IF(P31<=0,"Current",IF(P31<=30,"1-30",IF(P31<=60,"31-60",IF(P31<=90,"61-90","90+"))))) -> 90+ | R31: =TEXT(C31,"mmm") -> Apr | S31: =TEXT(C31,"yyyy-mm") -> 2025-04
... A39: INV-1100 | B39: Riverside Health | C39: 45777 | D39: 45807 | E39: 45807 | F39: South | G39: Claims Review | H39: 1667.45 | I39: 1397.57 | J39: Partial | K39: Yes | L39: Coding issue | M39: R. Nguyen | N39: =H39-I39 -> 269.88 | O39: =IF(E39="","",E39-C39) -> 30 | P39: =IF(N39<=0,0,TODAY()-D39) -> 290 | Q39: =IF(N39<=0,"Paid",IF(P39<=0,"Current",IF(P39<=30,"1-30",IF(P39<=60,"31-60",IF(P39<=90,"61-90","90+"))))) -> 90+ | R39: =TEXT(C39,"mmm") -> Apr | S39: =TEXT(C39,"yyyy-mm") -> 2025-04
A40: INV-1214 | B40: Canyon Creek Medical | C40: 45777 | D40: 45807 | F40: South | G40: Lab Services | H40: 1556.91 | I40: 0 | J40: Unpaid | K40: Yes | L40: Eligibility issue | M40: K. Brown | N40: =H40-I40 -> 1556.91 | O40: =IF(E40="","",E40-C40) | P40: =IF(N40<=0,0,TODAY()-D40) -> 290 | Q40: =IF(N40<=0,"Paid",IF(P40<=0,"Current",IF(P40<=30,"1-30",IF(P40<=60,"31-60",IF(P40<=90,"61-90","90+"))))) -> 90+ | R40: =TEXT(C40,"mmm") -> Apr | S40: =TEXT(C40,"yyyy-mm") -> 2025-04
A41: INV-1099 | B41: Parkview Internal Medicine | C41: 45779 | D41: 45809 | E41: 45805 | F41: North | G41: Revenue Audit | H41: 4936.36 | I41: 2869.76 | J41: Partial | K41: Yes | L41: Underpayment | M41: S. Patel | N41: =H41-I41 -> 2066.6 | O41: =IF(E41="","",E41-C41) -> 26 | P41: =IF(N41<=0,0,TODAY()-D41) -> 288 | Q41: =IF(N41<=0,"Paid",IF(P41<=0,"Current",IF(P41<=30,"1-30",IF(P41<=60,"31-60",IF(P41<=90,"61-90","90+"))))) -> 90+ | R41: =TEXT(C41,"mmm") -> May | S41: =TEXT(C41,"yyyy-mm") -> 2025-05
A42: INV-1194 | B42: Horizon Medical | C42: 45779 | D42: 45809 | F42: South | G42: Lab Services | H42: 935.23 | I42: 688.62 | J42: Partial | K42: No | L42: None | M42: K. Brown | N42: =H42-I42 -> 246.61 | O42: =IF(E42="","",E42-C42) | P42: =IF(N42<=0,0,TODAY()-D42) -> 288 | Q42: =IF(N42<=0,"Paid",IF(P42<=0,"Current",IF(P42<=30,"1-30",IF(P42<=60,"31-60",IF(P42<=90,"61-90","90+"))))) -> 90+ | R42: =TEXT(C42,"mmm") -> May | S42: =TEXT(C42,"yyyy-mm") -> 2025-05
A43: INV-1171 | B43: Hillcrest Diagnostics | C43: 45780 | D43: 45810 | F43: East | G43: Lab Services | H43: 1245.65 | I43: 0 | J43: Unpaid | K43: Yes | L43: Missing info | M43: A. Lopez | N43: =H43-I43 -> 1245.65 | O43: =IF(E43="","",E43-C43) | P43: =IF(N43<=0,0,TODAY()-D43) -> 287 | Q43: =IF(N43<=0,"Paid",IF(P43<=0,"Current",IF(P43<=30,"1-30",IF(P43<=60,"31-60",IF(P43<=90,"61-90","90+"))))) -> 90+ | R43: =TEXT(C43,"mmm") -> May | S43: =TEXT(C43,"yyyy-mm") -> 2025-05
A44: INV-1019 | B44: Westgate Family Health | C44: 45781 | D44: 45811 | E44: 45827 | F44: South | G44: Revenue Audit | H44: 5718.3 | I44: 5718.3 | J44: Paid | K44: No | L44: None | M44: K. Brown | N44: =H44-I44 -> 0 | O44: =IF(E44="","",E44-C44) -> 46 | P44: =IF(N44<=0,0,TODAY()-D44) -> 0 | Q44: =IF(N44<=0,"Paid",IF(P44<=0,"Current",IF(P44<=30,"1-30",IF(P44<=60,"31-60",IF(P44<=90,"61-90","90+"))))) -> Paid | R44: =TEXT(C44,"mmm") -> May | S44: =TEXT(C44,"yyyy-mm") -> 2025-05
A45: INV-1148 | B45: Pioneer Care | C45: 45783 | D45: 45813 | E45: 45813 | F45: West | G45: RCM Consulting | H45: 2994.86 | I45: 2994.86 | J45: Paid | K45: No | L45: None | M45: R. Nguyen | N45: =H45-I45 -> 0 | O45: =IF(E45="","",E45-C45) -> 30 | P45: =IF(N45<=0,0,TODAY()-D45) -> 0 | Q45: =IF(N45<=0,"Paid",IF(P45<=0,"Current",IF(P45<=30,"1-30",IF(P45<=60,"31-60",IF(P45<=90,"61-90","90+"))))) -> Paid | R45: =TEXT(C45,"mmm") -> May | S45: =TEXT(C45,"yyyy-mm") -> 2025-05
A46: INV-1131 | B46: NorthStar Clinic | C46: 45784 | D46: 45814 | E46: 45800 | F46: North | G46: Billing Support | H46: 1595.48 | I46: 1595.48 | J46: Paid | K46: No | L46: None | M46: A. Lopez | N46: =H46-I46 -> 0 | O46: =IF(E46="","",E46-C46) -> 16 | P46: =IF(N46<=0,0,TODAY()-D46) -> 0 | Q46: =IF(N46<=0,"Paid",IF(P46<=0,"Current",IF(P46<=30,"1-30",IF(P46<=60,"31-60",IF(P46<=90,"61-90","90+"))))) -> Paid | R46: =TEXT(C46,"mmm") -> May | S46: =TEXT(C46,"yyyy-mm") -> 2025-05
A47: INV-1170 | B47: Canyon Creek Medical | C47: 45787 | D47: 45817 | E47: 45840 | F47: East | G47: Lab Services | H47: 1889.83 | I47: 1889.83 | J47: Paid | K47: No | L47: None | M47: R. Nguyen | N47: =H47-I47 -> 0 | O47: =IF(E47="","",E47-C47) -> 53 | P47: =IF(N47<=0,0,TODAY()-D47) -> 0 | Q47: =IF(N47<=0,"Paid",IF(P47<=0,"Current",IF(P47<=30,"1-30",IF(P47<=60,"31-60",IF(P47<=90,"61-90","90+"))))) -> Paid | R47: =TEXT(C47,"mmm") -> May | S47: =TEXT(C47,"yyyy-mm") -> 2025-05
...

Sheet Pivot_Tables
A1: Row Labels | B1: Sum of Billed_Amount | C1: Sum of Paid_Amount | E1: Row Labels | F1: Count of Invoice_ID
A2: 2025-03 | B2: 2659.04 | C2: 888.34 | E2: Coding issue | F2: 1 | H2: Average of Days_to_Pay
A3: 2025-04 | B3: 6589.59 | C3: 2632.67 | E3: Late payment | F3: 2 | H3: 35.76699
A4: 2025-05 | B4: 5036.44 | C4: 2839.11 | E4: Missing info | F4: 2
A5: 2025-06 | B5: 5985.87 | C5: 1600.45 | E5: Underpayment | F5: 1
A6: 2025-07 | B6: 6735.42 | C6: 4914.87 | E6: Grand Total | F6: 6
A7: 2025-09 | B7: 10968.76 | C7: 4407.27
A8: 2025-10 | B8: 1515.35 | C8: 433.89 | H8: Row Labels | I8: Count of Invoice_ID
A9: 2025-12 | B9: 2022.39 | C9: 1380.97 | H9: No | I9: 176
A10: Grand Total | B10: 41512.86 | C10: 19097.57 | H10: Yes | I10: 84
E11: Row Labels | F11: Sum of Outstanding_Balance | H11: Grand Total | I11: 260
E12: 31-60 | F12: 641.42
E13: 90+ | F13: 21773.87
E14: Grand Total | F14: 22415.29
A16: Row Labels | B16: Sum of Billed_Amount | C16: Sum of Paid_Amount
A17: Billing Support | B17: 6234.32 | C17: 3811.01
A18: Claims Review | B18: 8168.73 | C18: 3933.48
A19: Imaging | B19: 13007.86 | C19: 6795.58
A20: Lab Services | B20: 1529.33 | C20: 942.61 | E20: Row Labels | F20: Count of Invoice_ID
A21: RCM Consulting | B21: 12572.62 | C21: 3614.89 | E21: Paid | F21: 162
A22: Grand Total | B22: 41512.86 | C22: 19097.57 | E22: Partial | F22: 53
E23: Unpaid | F23: 45
E24: Grand Total | F24: 260
A25: Row Labels | B25: Sum of Billed_Amount | C25: Sum of Paid_Amount
A26: West | B26: 41512.86 | C26: 19097.57
A27: Grand Total | B27: 41512.86 | C27: 19097.57
E29: Days_Past_Due | F29: (Multiple Items)
E31: Sum of Outstanding_Balance
E32: 169889.43
E35: Count of Invoice_ID
E36: 260
A37: Row Labels | B37: Sum of Billed_Amount | C37: Sum of Paid_Amount
A38: 2025-03 | B38: 2659.04 | C38: 888.34
A39: 2025-04 | B39: 6589.59 | C39: 2632.67
A40: 2025-05 | B40: 5036.44 | C40: 2839.11
A41: 2025-06 | B41: 5985.87 | C41: 1600.45
A42: 2025-07 | B42: 6735.42 | C42: 4914.87
A43: 2025-09 | B43: 10968.76 | C43: 4407.27
A44: 2025-10 | B44: 1515.35 | C44: 433.89
A45: 2025-12 | B45: 2022.39 | C45: 1380.97
...

Sheet Revenue_Dashboard_v2.xlsx
A1: Total Billed | B1: Total Paid | C1: Outstanding | D1: Collection Rate | E1: Avg Days to Pay | F1: Unpaid Invoices | G1: $ Past Due 30+ | H1: Exception Rate
A2: =GETPIVOTDATA("Sum of Billed_Amount",Pivot_Tables!$A$1) -> 41512.86 | B2: =GETPIVOTDATA("Sum of Paid_Amount",Pivot_Tables!$A$1) -> 19097.57 | C2: =GETPIVOTDATA("Outstanding_Balance",Pivot_Tables!$E$11) -> 22415.29 | D2: =IFERROR(B2/A2,0) -> 0.46003985 | E2: =GETPIVOTDATA("Days_to_Pay",Pivot_Tables!$H$2) -> 35.76699 | F2: =GETPIVOTDATA("Invoice_ID",Pivot_Tables!$E$20,"Payment_Status","Unpaid") -> 45 | G2: =GETPIVOTDATA("Outstanding_Balance",Pivot_Tables!$E$31) -> 169889.43 | H2: =IFERROR(H3/H4,0) -> 0.32307692
H3: =GETPIVOTDATA("Invoice_ID",Pivot_Tables!$H$8,"Denial_or_Exception","Yes") -> 84
H4: =GETPIVOTDATA("Invoice_ID",Pivot_Tables!$E$35) -> 260
